Workbook
Name Aer_aisle: Аэропорт!$D$36
Name Aer_auto_share: Аэропорт!$D$29
Name Aer_bag_mass: Аэропорт!$D$12
Name Aer_bags_day: Аэропорт!$D$11
Name Aer_base_labor: Аэропорт!$D$50
Name Aer_budget: Аэропорт!$D$19
Name Aer_clearance: Аэропорт!$D$37
Name Aer_consum_per_robot: Аэропорт!$D$58
Name Aer_divisible: Аэропорт!$D$31
Name Aer_driver_share: Аэропорт!$D$47
Name Aer_fleet_per_shift: Аэропорт!$D$54
Name Aer_fleet_sal: Аэропорт!$D$55
Name Aer_flights_day: Аэропорт!$D$9
Name Aer_flights_peak_h: Аэропорт!$D$10
Name Aer_fte_target: Аэропорт!$D$48
Name Aer_gates: Аэропорт!$D$8
Name Aer_handling_req: Аэропорт!$D$40
Name Aer_horizon: Аэропорт!$D$20
Name Aer_hours_day: Аэропорт!$D$26
Name Aer_indoor_req: Аэропорт!$D$41
Name Aer_integration: Аэропорт!$D$57
Name Aer_L: Аэропорт!$D$32
Name Aer_labor_target: Аэропорт!$D$49
Name Aer_lift_share: Аэропорт!$D$34
Name Aer_lift_time: Аэропорт!$D$35
Name Aer_loss_k: Аэропорт!$D$53
Name Aer_noise: Аэропорт!$D$17
Name Aer_ops_day: Аэропорт!$D$27
Name Aer_other_effects: Аэропорт!$D$59
Name Aer_outdoor_req: Аэропорт!$D$38
Name Aer_peak_ops_h: Аэропорт!$D$28
Name Aer_power_kw: Аэропорт!$D$18
Name Aer_ramp_staff: Аэропорт!$D$13
Name Aer_repl_body: Аэропорт!$D$45
Name Aer_repl_forks: Аэропорт!$D$42
Name Aer_repl_platform: Аэропорт!$D$43
Name Aer_repl_tow: Аэропорт!$D$44
Name Aer_S_apron: Аэропорт!$D$7
Name Aer_S_terminal: Аэропорт!$D$6
Name Aer_sal_ramp: Аэропорт!$D$14
Name Aer_sal_target: Аэропорт!$D$51
Name Aer_shift_h: Аэропорт!$D$25
Name Aer_shifts: Аэропорт!$D$24
Name Aer_site_pct: Аэропорт!$D$56
Name Aer_speed_cap: Аэропорт!$D$33
Name Aer_task_class: Аэропорт!$D$39
Name Aer_temp_min: Аэропорт!$D$46
Name Aer_temp_min_ds: Аэропорт!$D$16
Name Aer_turnover: Аэропорт!$D$52
Name Aer_turnover_ds: Аэропорт!$D$15
Name Aer_unit_mass: Аэропорт!$D$30
Name Cat_auton: Каталог!$M$4:$M$13
Name Cat_cap: Каталог!$K$4:$K$13
Name Cat_charge: Каталог!$N$4:$N$13
Name Cat_code: Каталог!$A$4:$A$13
Name Cat_conf: Каталог!$AE$4:$AE$13
Name Cat_date: Каталог!$AF$4:$AF$13
Name Cat_handling: Каталог!$AA$4:$AA$13
Name Cat_hgt: Каталог!$Q$4:$Q$13
Name Cat_indoor: Каталог!$Z$4:$Z$13

Sheet Легенда
A1: ЭКОНОМИЧЕСКАЯ МОДЕЛЬ ПЛАТФОРМЫ ПОДБОРА РОБОТИЗИРОВАННЫХ РЕШЕНИЙ (кейс ФЦ БАС) — v1.1
A3: Назначение | B3: Прозрачная расчётная модель по п. 3.5 ТЗ: состав оборудования, CAPEX, OPEX, годовой эффект, срок окупаемости, ROI, TCO, чувствительность, интерпретация. Один лист = один тип объекта (Склад / Аэропорт / Медучреждение).
A4: Как читать листы объектов | B4: Блок 1 — параметры объекта из демо-датасета (Датасеты_хакатон.xlsx). Блок 2 — параметры процесса и допущения команды. Блок 3 — расчётный движок: каждая колонка = один прогон сценария (решение × модель приобретения × вариант чувствительности). Блок 4 — сравнение сценариев. Блок 5 — денежный поток по годам. Блок 6 — чувствительность. Блок 7 — заключение.
A5: Цветовая легенда | B5: Синий шрифт — вводимые значения (из датасета или каталога). Жёлтая заливка — допущения команды (обязательно документированы в столбце «Источник»). Чёрный — формулы. Зелёный — ссылки на другой лист. Зелёная заливка — ключевые результаты.
A6: Что менять | B6: Меняйте только синие ячейки (столбец «Значение») на листах Склад / Аэропорт / Медучреждение / Нормативы / Каталог. Все результаты пересчитываются автоматически. Диапазоны min/max — для валидации ввода в платформе.
A7: Сценарии | B7: Базовый (без роботизации) + не менее двух роботизированных: «Покупка» (CAPEX у заказчика) и «RaaS» (аренда/роботы как услуга: ежемесячный платёж, CAPEX только на интеграцию и подготовку объекта). Для каждого объекта также добавлен альтернативный продукт (Покупка B).
A8: Источники данных | B8: Датасет: Датасеты_хакатон.xlsx (листы Склад/Аэропорт/Медучреждение). Цены: catalog_export_v4.csv (столбец «Цена изделия», с НДС, без доставки и ПНР — Дополнения п.6). ТТХ: Примеры_решений_типы_объектов.docx и описания в каталоге. Формулы: ТЗ п.3.5, Дополнения п.2.
A9: Ограничение | B9: Результат является предварительной оценкой (экспресс-предынвестиционная) и требует верификации при обследовании объекта (ТЗ п.3.7.5).
A10: Версия модели | B10: v1.1 от 17.09.2026. Изменения к v1.0: в каталог добавлены поля «класс задачи», «способ обработки груза», «допуск в помещения»; коэффициент замещения труда задаётся парой «задача × способ обработки» (блок 2), а не роботом; добавлены фильтры класса задачи, способа обработки и допуска в помещения. Демо-результаты не изменились. Версия исходных данных: датасет (хакатон), каталог v4.

Sheet Каталог
A1: КАТАЛОГ РЕШЕНИЙ (выборка для демо): цены — catalog_export_v4.csv; ТТХ — Примеры_решений_типы_объектов.docx / описания каталога / допущения
A3: Код решения | B3: Наименование | C3: Производитель | D3: Тип | E3: Подтип | F3: Сценарий (каталог) | G3: Статус (каталог) | H3: УГТ | I3: Рын. потенциал | J3: Цена изделия, руб. (с НДС) | K3: Грузоподъёмность, кг | L3: Макс. скорость, м/с | M3: Автономность, ч | N3: Время зарядки, мин | O3: Длина, мм | P3: Ширина, мм | Q3: Высота, мм | R3: Темп. мин, °C | S3: Темп. макс, °C | T3: Ср. потребляемая мощность, кВт | U3: Заявленная производительность (справочно) | V3: Время загрузки, с | W3: Время разгрузки, с | X3: Коэф. замещения (справочно; в расчёте — по паре задача×способ обработки, блок 2 листа объекта) | Y3: Уличная эксплуатация (1/0) | Z3: Допуск в помещения (1/0) | AA3: Способ обработки груза | AB3: Класс задачи | AC3: Тип навигации | AD3: Источник ТТХ | AE3: ТТХ подтверждены | AF3: Дата актуализации | AG3: Примечание / допущения
A4: DMR-CARRIER-P | B4: DMR Carrier P (FMR, вилочный AMR) | C4: ООО "Диком-Сервис" | D4: Мобильные роботы | E4: FMR | F4: Внутрискладская логистика | G4: piloting | H4: 8 | I4: 4 | J4: 4300000 | K4: 1500 | L4: 1.5 | M4: 10 | N4: 90 | O4: 1975 | P4: 1000 | Q4: 2050 | R4: 5 | S4: 35 | T4: 3 | U4: 40–60 паллет/ч (типичный проект, докс организатора) | V4: 60 | W4: 60 | X4: 0.8 | Y4: 0 | Z4: 1 | AA4: вилы | AB4: транспорт | AC4: SLAM (лидары) | AD4: Docx организатора (пример FMR); цена — CSV каталога | AE4: Частично | AF4: 2026-09-16 | AG4: Габариты в docx даны как В×Ш×Г 2050×1975×1000 — принято: длина 1975, ширина 1000. Время зарядки, темп. диапазон, мощность, времена операций — допущения команды.
A5: AK-2000-2 | B5: AK-2000-2 (FMR) | C5: ООО "ГК Автомакон" | D5: Автономные наземные ТС | E5: FMR | F5: Внутрискладская логистика | G5: operation | H5: 9 | I5: 4 | J5: 2940000 | K5: 1500 | L5: 1.5 | M5: 10 | N5: 90 | O5: 1975 | P5: 1000 | Q5: 2050 | R5: 5 | S5: 35 | T5: 3 | U5: Кейс: 67 роботов в РЦ X5 «Новая Рига» | V5: 60 | W5: 60 | X5: 0.8 | Y5: 0 | Z5: 1 | AA5: вилы | AB5: транспорт | AC5: SLAM | AD5: ТТХ приняты по аналогу FMR (DMR Carrier P) — ТРЕБУЕТ ПРОВЕРКИ по сайту производителя | AE5: Нет | AF5: 2026-09-16 | AG5: В каталоге ТТХ отсутствуют; по Дополнениям п.4 недостающие ТТХ заполняются из открытых источников. До подтверждения — решение помечается «требует проверки».
A6: RONAVI-H1500 | B6: Ronavi H1500 (AMR, до 1500 кг) | C6: ООО "Ронави Роботикс" | D6: Мобильные роботы | E6: AMR | F6: Внутрискладская логистика | G6: operation | H6: 8 | I6: 4 | J6: 2700000 | K6: 1500 | L6: 1.5 | M6: 6 | N6: 18 | O6: 1044 | P6: 654 | Q6: 380 | R6: 5 | S6: 25 | T6: 1 | U6: 80–100 паллет/ч (типовая конфигурация зоны, docx) | V6: 30 | W6: 30 | X6: 0.6 | Y6: 0 | Z6: 1 | AA6: платформа | AB6: транспорт | AC6: QR-метки + SLAM | AD6: Docx организатора; цена — CSV каталога | AE6: Да | AF6: 2026-09-16 | AG6: Робот подъёмного типа: требует передачи паллет через станции/конвейер (не забирает с пола) — отсюда коэф. замещения 0.6 и повышенная доля подготовки объекта.
A7: RONAVI-M | B7: Ronavi M (AMR для стеллажей/тележек, до 1200 кг) | C7: ООО "Ронави Роботикс" | D7: Мобильные роботы | E7: AMR | F7: Внутрискладская логистика | G7: piloting | H7: 7 | I7: 4 | J7: 2400000 | K7: 1200 | L7: 1.5 | M7: 6 | N7: 18 | O7: 1044 | P7: 654 | Q7: 380 | R7: 5 | S7: 30 | T7: 1 | U7: — | V7: 45 | W7: 45 | X7: 0.8 | Y7: 0 | Z7: 1 | AA7: платформа | AB7: транспорт | AC7: QR-метки + SLAM | AD7: Описание каталога (назначение, грузоподъёмность); остальные ТТХ по аналогу H1500 — ТРЕБУЮТ ПРОВЕРКИ | AE7: Частично | AF7: 2026-09-16 | AG7: Робот с поворотным кругом для транспортировки мобильных стеллажей/столиков — подходит под больничные тележки (подъезд под тележку).
A8: MOROS-AMR800 | B8: AMR 800 (Морос, до 800 кг) | C8: ООО "Морос" | D8: Мобильные роботы | E8: AMR | F8: Внутрискладская логистика | G8: operation | H8: 9 | I8: 4 | J8: 1800000 | K8: 800 | L8: 1.5 | M8: 20 | N8: 60 | O8: 1100 | P8: 600 | Q8: 230 | R8: 5 | S8: 30 | T8: 1 | U8: Кейс: 27 роботов на складах e-commerce | V8: 45 | W8: 45 | X8: 0.8 | Y8: 0 | Z8: 1 | AA8: платформа | AB8: транспорт | AC8: SLAM | AD8: Описание каталога (AMR 1500: 1100×600×230, 1.5 м/с, проезд от 680 мм, 22 ч) — приняты по аналогу для AMR 800; ТРЕБУЮТ ПРОВЕРКИ | AE8: Частично | AF8: 2026-09-16 | AG8: Подходит под перевозку тележек до 800 кг.
A9: RONAVI-SD | B9: Ronavi SD (AMR, до 10 кг) | C9: ООО "Ронави Роботикс" | D9: Мобильные роботы | E9: AMR | F9: Внутрискладская логистика | G9: piloting | H9: 8 | I9: 4 | J9: 1400000 | K9: 10 | L9: 2.5 | M9: 10 | N9: 60 | O9: 420 | P9: 400 | Q9: 200 | R9: 5 | S9: 30 | T9: 0.3 | U9: — | V9: 20 | W9: 20 | X9: 0.5 | Y9: 0 | Z9: 1 | AA9: кузов | AB9: транспорт | AC9: QR-метки | AD9: Docx организатора (пример для медучреждения) | AE9: Да | AF9: 2026-09-16 | AG9: Мин. ширина проезда 700 мм. Применим только для лёгкой доставки (медикаменты, пробы) — исключается фильтром по грузоподъёмности для процесса «тележки».
A10: PUDUBOT-2 | B10: PuduBot 2 (робот-доставщик) | C10: Pudu Robotics (внешний) | D10: Мобильные роботы | E10: Робот-доставщик | F10: Доставка внутри помещений | G10: внешний источник | K10: 10 | L10: 1.2 | M10: 12 | N10: 240 | O10: 580 | P10: 535 | Q10: 1290 | R10: 5 | S10: 35 | T10: 0.3 | U10: 10 кг на полку | V10: 20 | W10: 20 | X10: 0.5 | Y10: 0 | Z10: 1 | AA10: кузов | AB10: транспорт | AC10: VSLAM + лазерный SLAM | AD10: Docx организатора; цены в каталоге ФЦ БАС нет | AE10: Частично | AF10: 2026-09-16 | AG10: Нет цены в каталоге организатора → в расчёт не включается без ввода цены; отсутствует в реестре отечественных решений.
A11: COGNITIVE-TUG | B11: Беспилотный тягач (Cognitive Pilot) | C11: АО "Когнитив Пилот" | D11: Автономные наземные ТС | E11: Беспилотный тягач | F11: Перевозка грузов на закрытых площадках | G11: operation | H11: 8 | I11: 3 | J11: 4000000 | K11: 3000 | L11: 4.17 | M11: 24 | N11: 30 | O11: 2300 | P11: 1400 | Q11: 1500 | R11: -40 | S11: 45 | T11: 6 | U11: Кейс: 45 тягачей для Пулково (перевозка багажа) | V11: 180 | W11: 180 | X11: 0.8 | Y11: 1 | Z11: 0 | AA11: буксировка | AB11: транспорт | AC11: Мультисенсорный автопилот | AD11: Docx организатора; цена — CSV каталога | AE11: Да | AF11: 2026-09-16 | AG11: Гибридная СУ: «энергия» смоделирована как эквивалент 6 кВт·ч/ч работы (топливо+электро) — допущение. Скорость принята рабочая 15 км/ч (4.17 м/с) из диапазона 5–25 км/ч. Время сцепки/расцепки тележек 180 с — допущение.
A12: EVOCARGO-N1 | B12: EVOCARGO N1 (беспилотный электрогрузовик) | C12: ООО "Эвокарго" | D12: Автономные наземные ТС | E12: Беспилотный грузовик | F12: Перевозка грузов на закрытых площадках | G12: operation | H12: 9 | I12: 5 | J12: 6000000 | K12: 2000 | L12: 5.56 | M12: 8 | N12: 30 | O12: 5000 | P12: 1800 | Q12: 2200 | R12: -40 | S12: 50 | T12: 6 | U12: 6 европаллет; запас хода 150–200 км | V12: 240 | W12: 240 | X12: 0.8 | Y12: 1 | Z12: 0 | AA12: кузов | AB12: транспорт | AC12: Автопилот L4–5 | AD12: Docx организатора; цена — CSV каталога | AE12: Да | AF12: 2026-09-16 | AG12: Автономность 8 ч оценена из АКБ 36 кВт·ч при 6 кВт·ч/ч (допущение). Скорость принята 20 км/ч (5.56 м/с). Погрузка/разгрузка 240 с — допущение (перегрузка багажных контейнеров).
A13: MARK-2-SE | B13: MARK 2 SE (робот-уборщик) | C13: ООО "Р2Б" | D13: Мобильные роботы | E13: Робот-уборщик | F13: Уборка помещений | G13: operation | H13: 9 | I13: 4 | J13: 1900000 | K13: 0 | L13: 1 | M13: 3 | N13: 120 | O13: 860 | P13: 610 | Q13: 980 | R13: 5 | S13: 35 | T13: 1 | U13: до 1000 м²/ч | V13: 0 | W13: 0 | X13: 0.7 | Y13: 0 | Z13: 1 | AA13: щётки | AB13: уборка | AC13: Лидар + камеры | AD13: Docx организатора; цена — CSV каталога | AE13: Да | AF13: 2026-09-16 | AG13: Для процесса «уборка» (расчёт по площади, не по рейсам) — в демо-сценарии не используется; включён для полноты каталога и расширения модели.
A15: Жёлтая заливка = ТТХ приняты по аналогу или являются допущением команды (Дополнения п.4: заполняются из открытых источников и помечаются как требующие проверки). Коэф. замещения труда, времена загрузки/разгрузки и мощность — экспертные допущения команды для всех решений.

Sheet Нормативы
A1: ГЛОБАЛЬНЫЕ НОРМАТИВЫ И ДОПУЩЕНИЯ (используются всеми объектами)
A3: Код (имя ячейки) | B3: Норматив | C3: Ед. изм. | D3: Значение | E3: Min | F3: Max | G3: Источник / обоснование | H3: Тип
A4: N_fot | B4: Коэффициент начислений на ФОТ (страховые взносы) | C4: коэф. | D4: 1.302 | E4: 1.302 | F4: 1.302 | G4: Датасет (все листы): ОПФ 22% + ОМС 5.1% + ОСС 2.9% + НСиПЗ 0.2% = 30.2% | H4: норматив/датасет | I4: payroll_multiplier
A5: N_util | B5: Коэффициент загрузки робота (доля продуктивного времени: зарядка, ожидание, простои) | C5: доля | D5: 0.8 | E5: 0.7 | F5: 0.85 | G5: Датасет, лист «Легенда»: типовой KPI AMR 70–85% | H5: норматив/датасет | I5: productive_time_share
A6: N_avail | B6: Коэффициент технической готовности (доступности) робота | C6: доля | D6: 0.9 | E6: 0.9 | F6: 0.98 | G6: Допущение команды: плановое ТО и отказы; типовой SLA вендоров 95–98% | H6: допущение | I6: technical_availability
A7: N_reserve | B7: Резерв парка роботов на пиковую нагрузку | C7: доля | D7: 0.1 | E7: 0.15 | F7: 0.2 | G7: Датасет, лист «Легенда»: резерв 15–20% | H7: норматив/датасет | I7: fleet_reserve_share
A8: N_kv | B8: Отношение средней эксплуатационной скорости к максимальной (разгон, повороты, трафик, зоны людей) | C8: коэф. | D8: 1 | E8: 0.5 | F8: 0.8 | G8: Допущение команды (практика проектов AMR); проверяется имитацией | H8: допущение | I8: operating_speed_factor
A9: N_charger_ratio | B9: Роботов на одну зарядную станцию | C9: шт./станцию | D9: 2 | E9: 2 | F9: 6 | G9: Допущение команды (opportunity charging) | H9: допущение | I9: robots_per_charger
A10: N_charger_price | B10: Стоимость зарядной станции с монтажом | C10: руб. | D10: 1000 | E10: 150000 | F10: 500000 | G10: Допущение команды (оценка рынка) | H10: допущение | I10: charger_installed_price
A11: N_charger_kw | B11: Мощность одной зарядной станции | C11: кВт | D11: 5 | E11: 3 | F11: 10 | G11: Допущение команды (типовые станции AMR 3–10 кВт) | H11: допущение | I11: charger_power_kw
A12: N_sw_pct | B12: ПО управления флотом (FMS), разовая лицензия и внедрение, % от стоимости оборудования | C12: доля | D12: 0.1 | E12: 0.05 | F12: 0.15 | G12: Допущение команды | H12: допущение | I12: fms_upfront_share
A13: N_delivery_pct | B13: Доставка оборудования, % от стоимости оборудования | C13: доля | D13: 0.05 | E13: 0.01 | F13: 0.05 | G13: Допущение команды; Дополнения п.6: доставка не включена в цену | H13: допущение | I13: delivery_share
A14: N_pnr_pct | B14: Пусконаладочные работы, % от стоимости оборудования | C14: доля | D14: 0.1 | E14: 0.03 | F14: 0.1 | G14: Допущение команды; Дополнения п.6: ПНР не включены в цену | H14: допущение | I14: commissioning_share
A15: N_training | B15: Обучение персонала заказчика (разово на проект) | C15: руб. | D15: 500 | E15: 100000 | F15: 1000000 | G15: Допущение команды | H15: допущение | I15: training_cost
... A33: N_pb_mid | B33: Граница «средней целесообразности»: срок окупаемости до, лет | C33: лет | D33: 4 | E33: 4 | F33: 7 | G33: ТЗ п.3.5.7 | H33: норматив/датасет | I33: medium_payback_years
A34: N_sens | B34: Шаг анализа чувствительности (±) | C34: доля | D34: 0.2 | E34: 0.1 | F34: 0.3 | G34: Допущение команды (ТЗ п.3.5.6 — минимум 3 параметра) | H34: допущение
A35: N_loss_k_default | B35: Коэффициент потерь рабочего времени персонала (отпуск, болезнь) — по умолчанию для объектов без данных | C35: доля | D35: 0.25 | E35: 0.15 | F35: 0.35 | G35: Датасет «Склад»: 25%; для аэропорта и медучреждения применён как допущение | H35: допущение | I35: staff_time_loss_share

Sheet Склад
A1: ОБЪЕКТ: СКЛАД — процесс: перемещение паллет (приёмка → хранение, хранение → отгрузка)
A2: Синие ячейки — ввод; жёлтая заливка — допущения команды; чёрные — формулы. Результаты помечены зелёной заливкой.
A4: БЛОК 1. ПАРАМЕТРЫ ОБЪЕКТА (демо-датасет организатора, лист «Склад»)
A5: Код | B5: Параметр | C5: Ед. изм. | D5: Значение | E5: Min | F5: Max | G5: Источник / обоснование | H5: Тип
A6: Skl_S_total | B6: Общая площадь склада | C6: м² | D6: 20000 | E6: 10000 | F6: 100000 | G6: Датасет, лист «Склад» | H6: датасет
A7: Skl_S_active | B7: Площадь активной (роботизируемой) зоны | C7: м² | D7: 10000 | E7: 5000 | F7: 50000 | G7: Датасет, лист «Склад» (50% общей площади) | H7: датасет
A8: Skl_aisle_main | B8: Ширина главных проездов | C8: м | D8: 3.5 | E8: 2.5 | F8: 6 | G8: Датасет, лист «Склад» — определяет допустимые габариты робота | H8: датасет
A9: Skl_aisle_rack | B9: Ширина рабочих проходов между стеллажами | C9: м | D9: 2.8 | E9: 1.5 | F9: 4.5 | G9: Датасет, лист «Склад» | H9: датасет
A10: Skl_shifts | B10: Количество рабочих смен в сутки | C10: смен | D10: 2 | E10: 1 | F10: 3 | G10: Датасет, лист «Склад» | H10: датасет | I10: shifts_per_day
A11: Skl_shift_h | B11: Продолжительность смены (с учётом перерывов) | C11: ч | D11: 11 | E11: 10 | F11: 11 | G11: Датасет, лист «Склад» | H11: датасет | I11: operating_hours_per_day
A12: Skl_days | B12: Рабочих дней в году | C12: дн. | D12: 365 | E12: 365 | F12: 365 | G12: Датасет, лист «Склад» | H12: датасет
A13: Skl_peak_k | B13: Пиковый коэффициент нагрузки (макс. час / средний час) | C13: коэф. | D13: 1.5 | E13: 1.2 | F13: 2.5 | G13: Датасет, лист «Склад» | H13: датасет | I13: peak_factor
A14: Skl_in_pallets | B14: Объём приёмки | C14: поддон/сут | D14: 1000 | E14: 500 | F14: 5000 | G14: Датасет, лист «Склад» | H14: датасет | I14: operations_per_day
A15: Skl_out_pallets | B15: Объём отгрузки | C15: поддон/сут | D15: 1000 | E15: 500 | F15: 5000 | G15: Датасет, лист «Склад» | H15: датасет | I15: operations_per_day
A16: Skl_forklift_ops | B16: Операторы погрузчиков (численность, все смены) | C16: чел. | D16: 25 | E16: 5 | F16: 80 | G16: Датасет, лист «Склад» — целевая функция для автономных погрузчиков | H16: датасет
A17: Skl_sal_forklift | B17: Средняя з/п оператора погрузчика (gross) | C17: руб./мес. | D17: 120000 | E17: 80000 | F17: 170000 | G17: Датасет, лист «Склад» | H17: датасет | I17: fleet_operator_monthly_salary, target_monthly_salary
A18: Skl_loss_k | B18: Коэффициент потерь рабочего времени (отпуск, болезнь, текучесть) | C18: доля | D18: 0.25 | E18: 0.15 | F18: 0.35 | G18: Датасет, лист «Склад» | H18: датасет | I18: staff_time_loss_share
A19: Skl_pallet_mass | B19: Средняя масса грузовой единицы (паллет) | C19: кг | D19: 800 | E19: 200 | F19: 1500 | G19: Датасет, лист «Склад» | H19: датасет
A20: Skl_oversize_share | B20: Доля негабаритных/нестандартных грузов (остаётся ручной) | C20: доля | D20: 0.05 | E20: 0 | F20: 0.3 | G20: Датасет, лист «Склад» | H20: датасет
A21: Skl_power_kw | B21: Мощность электроснабжения (доступная) | C21: кВт | D21: 500 | E21: 100 | F21: 3000 | G21: Датасет, лист «Склад» | H21: датасет | I21: available_charging_power_kw
A22: Skl_budget | B22: Планируемый бюджет на роботизацию (CAPEX) | C22: млн руб. | D22: 80 | E22: 10 | F22: 500 | G22: Датасет, лист «Склад» | H22: датасет | I22: budget
A23: Skl_horizon | B23: Горизонт расчёта окупаемости | C23: лет | D23: 5 | E23: 3 | F23: 10 | G23: Датасет, лист «Склад» | H23: датасет | I23: horizon_years
A25: БЛОК 2. ПАРАМЕТРЫ ПРОЦЕССА И ДОПУЩЕНИЯ КОМАНДЫ
A26: Код | B26: Параметр | C26: Ед. изм. | D26: Значение | E26: Min | F26: Max | G26: Источник / обоснование | H26: Тип
A27: Skl_ops_day | B27: Объём операций процесса = приёмка + отгрузка (перемещение паллет док ↔ зона хранения) | C27: оп./сут | D27: =Skl_in_pallets+Skl_out_pallets -> 2000 | G27: Формула из датасета | H27: формула
A28: Skl_auto_share | B28: Доля автоматизируемых операций = 1 − доля негабарита | C28: доля | D28: 1 | G28: Формула из датасета | H28: формула | I28: automatable_share
A29: Skl_hours_day | B29: Часов работы процесса в сутки = смен × продолжительность смены | C29: ч | D29: =Skl_shifts*Skl_shift_h -> 22 | G29: Формула из датасета | H29: формула
A30: Skl_peak_ops_h | B30: Пиковая интенсивность = объём / часов × пиковый коэффициент | C30: оп./ч | D30: =Skl_ops_day/Skl_hours_day*Skl_peak_k -> 136.36364 | G30: Формула из датасета | H30: формула
A31: Skl_unit_mass | B31: Масса единицы груза (паллет) | C31: кг | D31: =Skl_pallet_mass -> 800 | G31: Датасет | H31: формула | I31: load_unit_mass_kg
A32: Skl_divisible | B32: Груз делимый на несколько рейсов (1) / неделимый (0) | C32: 1/0 | D32: 0 | E32: 0 | F32: 1 | G32: Допущение: паллет неделим — при недостаточной грузоподъёмности решение исключается | H32: допущение | I32: load_is_divisible
A33: Skl_L | B33: Средняя длина маршрута (док ↔ ячейка) = √(площадь активной зоны) | C33: м | D33: =SQRT(Skl_S_active) -> 100 | G33: Допущение команды: средняя дистанция перемещения ≈ корню из площади зоны (проверяется на 2D-схеме) | H33: формула | I33: one_way_route_m | J33: there is in input dataset
A34: Skl_speed_cap | B34: Ограничение скорости на объекте | C34: м/с | D34: 1.5 | E34: 0.5 | F34: 2 | G34: Допущение: 1.5 м/с — типовой лимит для AMR/FMR в зонах с людьми | H34: допущение | I34: site_speed_limit_mps | J34: метры в секунду
A35: Skl_lift_share | B35: Доля рейсов через лифт/подъёмник | C35: доля | D35: 0 | E35: 0 | F35: 1 | G35: Датасет: 1 этаж — лифты не требуются | H35: датасет | I35: lift_trip_share
A36: Skl_lift_time | B36: Время ожидания + проезда лифта (в один проход) | C36: с | D36: 0 | E36: 0 | F36: 300 | G36: Не применяется (1 этаж) | H36: датасет | I36: one_way_lift_seconds
A37: Skl_aisle | B37: Минимальная ширина прохода для фильтра решений | C37: м | D37: =MIN(Skl_aisle_main,Skl_aisle_rack) -> 2.8 | G37: Формула из датасета | H37: формула
A38: Skl_clearance | B38: Запас по ширине проезда для безопасного движения | C38: м | D38: 0.6 | E38: 0.3 | F38: 1 | G38: Допущение команды (по 0.3 м с каждой стороны) | H38: допущение
A39: Skl_outdoor_req | B39: Требуется уличная эксплуатация (1/0) | C39: 1/0 | D39: 0 | E39: 0 | F39: 1 | G39: Склад — закрытое отапливаемое помещение | H39: датасет
A40: Skl_task_class | B40: Класс задачи процесса | D40: транспорт | G40: транспорт (рейсы) / уборка (площадь) | H40: датасет
A41: Skl_handling_req | B41: Допустимые способы обработки груза (через ;) | D41: вилы;платформа | G41: Допущение команды: паллет с пола — вилы; платформа — через станции передачи (часть труда остаётся → 0.6) | H41: допущение
A42: Skl_indoor_req | B42: Работа внутри помещений (1/0) | C42: 1/0 | D42: 1 | E42: 0 | F42: 1 | G42: Уличные гибриды/грузовики не допускаются в помещения | H42: датасет
...

Sheet Аэропорт
A1: ОБЪЕКТ: АЭРОПОРТ — процесс: перевозка багажа перрон ↔ терминал (RAMP)
A2: Синие ячейки — ввод; жёлтая заливка — допущения команды; чёрные — формулы. Результаты помечены зелёной заливкой.
A4: БЛОК 1. ПАРАМЕТРЫ ОБЪЕКТА (демо-датасет организатора, лист «Аэропорт»)
A5: Код | B5: Параметр | C5: Ед. изм. | D5: Значение | E5: Min | F5: Max | G5: Источник / обоснование | H5: Тип
A6: Aer_S_terminal | B6: Суммарная площадь терминала(ов) | C6: м² | D6: 85000 | E6: 8000 | F6: 500000 | G6: Датасет, лист «Аэропорт» | H6: датасет
A7: Aer_S_apron | B7: Площадь перрона и технических зон | C7: м² | D7: 100000 | E7: 10000 | F7: 800000 | G7: Датасет, лист «Аэропорт» | H7: датасет
A8: Aer_gates | B8: Количество выходов на посадку | C8: шт. | D8: 20 | E8: 8 | F8: 50 | G8: Датасет, лист «Аэропорт» | H8: датасет
A9: Aer_flights_day | B9: Среднесуточное количество рейсов (взлёт+посадка) | C9: рейсов/сут | D9: 280 | E9: 30 | F9: 1200 | G9: Датасет, лист «Аэропорт» | H9: датасет
A10: Aer_flights_peak_h | B10: Пиковое количество рейсов в час | C10: рейсов/ч | D10: 32 | E10: 4 | F10: 120 | G10: Датасет, лист «Аэропорт» | H10: датасет
A11: Aer_bags_day | B11: Объём перемещения багажа | C11: ед./сут | D11: 35000 | E11: 3000 | F11: 300000 | G11: Датасет, лист «Аэропорт» | H11: датасет
A12: Aer_bag_mass | B12: Средняя масса единицы багажа | C12: кг | D12: 18 | E12: 10 | F12: 35 | G12: Датасет, лист «Аэропорт» | H12: датасет
A13: Aer_ramp_staff | B13: Численность персонала наземного обслуживания (рамп) | C13: чел. | D13: 320 | E13: 50 | F13: 2000 | G13: Датасет, лист «Аэропорт» | H13: датасет
A14: Aer_sal_ramp | B14: Средняя з/п сотрудника наземного обслуживания (gross) | C14: руб./мес. | D14: 100000 | E14: 70000 | F14: 150000 | G14: Датасет, лист «Аэропорт» | H14: датасет
A15: Aer_turnover_ds | B15: Годовая текучесть персонала | C15: доля | D15: 0.35 | E15: 0.15 | F15: 0.6 | G15: Датасет, лист «Аэропорт» | H15: датасет
A16: Aer_temp_min_ds | B16: Температура в неотапливаемых зонах (перрон, зима) | C16: °C | D16: -25 | E16: -40 | F16: 0 | G16: Датасет, лист «Аэропорт» | H16: датасет
A17: Aer_noise | B17: Ограничение по уровню шума | C17: дБА | D17: 70 | E17: 55 | F17: 80 | G17: Датасет, лист «Аэропорт» | H17: датасет
... A20: Aer_horizon | B20: Горизонт расчёта окупаемости | C20: лет | D20: 7 | E20: 5 | F20: 15 | G20: Датасет, лист «Аэропорт» | H20: датасет
A22: БЛОК 2. ПАРАМЕТРЫ ПРОЦЕССА И ДОПУЩЕНИЯ КОМАНДЫ
A23: Код | B23: Параметр | C23: Ед. изм. | D23: Значение | E23: Min | F23: Max | G23: Источник / обоснование | H23: Тип
A24: Aer_shifts | B24: Смен в сутки (круглосуточная работа аэропорта) | C24: смен | D24: 3 | E24: 2 | F24: 3 | G24: Допущение команды: режим 24/7, 3 смены по 8 ч | H24: допущение
A25: Aer_shift_h | B25: Продолжительность смены | C25: ч | D25: 8 | E25: 8 | F25: 12 | G25: Допущение команды | H25: допущение
A26: Aer_hours_day | B26: Часов работы процесса в сутки | C26: ч | D26: =Aer_shifts*Aer_shift_h -> 24 | G26: Формула | H26: формула
A27: Aer_ops_day | B27: Объём операций = рейсов × 2 (доставка багажа на борт + вывоз на выдачу) | C27: оп./сут | D27: =Aer_flights_day*2 -> 560 | G27: Формула из датасета | H27: формула
A28: Aer_peak_ops_h | B28: Пиковая интенсивность = пиковых рейсов/ч × 2 | C28: оп./ч | D28: =Aer_flights_peak_h*2 -> 64 | G28: Формула из датасета (пик задан напрямую, пиковый коэффициент не применяется) | H28: формула
A29: Aer_auto_share | B29: Доля автоматизируемых операций | C29: доля | D29: 0.9 | E29: 0.5 | F29: 1 | G29: Допущение: 10% рейсов (нестандартные стоянки, спецрейсы) остаются ручными | H29: допущение
A30: Aer_unit_mass | B30: Масса багажа одного рейса = багаж/сут ÷ рейсов/сут × масса единицы | C30: кг | D30: =Aer_bags_day/Aer_flights_day*Aer_bag_mass -> 2250 | G30: Формула из датасета | H30: формула
A31: Aer_divisible | B31: Груз делимый (1): багаж рейса можно везти несколькими рейсами робота | C31: 1/0 | D31: 1 | E31: 0 | F31: 1 | G31: Допущение | H31: допущение
A32: Aer_L | B32: Средняя длина маршрута (сортировка багажа ↔ стоянка ВС) = 2 × √(площадь перрона) | C32: м | D32: =2*SQRT(Aer_S_apron) -> 632.45553 | G32: Допущение команды (проверяется на схеме перрона) | H32: формула
A33: Aer_speed_cap | B33: Ограничение скорости на перроне | C33: м/с | D33: 4.17 | E33: 2 | F33: 7 | G33: Допущение: 15 км/ч — типовой лимит для перронной техники | H33: допущение
A34: Aer_lift_share | B34: Доля рейсов через лифт | C34: доля | D34: 0 | E34: 0 | F34: 1 | G34: Не применяется (перрон) | H34: датасет
A35: Aer_lift_time | B35: Время лифта | C35: с | D35: 0 | E35: 0 | F35: 300 | G35: Не применяется | H35: датасет
A36: Aer_aisle | B36: Минимальная ширина проезда (служебные проезды перрона) | C36: м | D36: 4 | E36: 3 | F36: 8 | G36: Допущение команды | H36: допущение
A37: Aer_clearance | B37: Запас по ширине проезда | C37: м | D37: 0.6 | E37: 0.3 | F37: 1 | G37: Допущение команды | H37: допущение
A38: Aer_outdoor_req | B38: Требуется уличная эксплуатация (1/0) | C38: 1/0 | D38: 1 | E38: 0 | F38: 1 | G38: Перрон — открытая зона (датасет: ограничения по погоде и допускам) | H38: датасет
A39: Aer_task_class | B39: Класс задачи процесса | D39: транспорт | G39: транспорт (рейсы) / уборка (площадь) | H39: датасет
A40: Aer_handling_req | B40: Допустимые способы обработки груза (через ;) | D40: буксировка;кузов | G40: Допущение команды: багажные тележки — буксировка; контейнеры — кузов | H40: допущение
A41: Aer_indoor_req | B41: Работа внутри помещений (1/0) | C41: 1/0 | D41: 0 | E41: 0 | F41: 1 | G41: Уличные гибриды/грузовики не допускаются в помещения | H41: датасет
A42: Aer_repl_forks | B42: Коэф. замещения труда: вилы | C42: доля | D42: 0.8 | E42: 0.5 | F42: 0.9 | G42: Допущение команды: полный цикл без станций; остаются высотные/нестандартные операции | H42: допущение
A43: Aer_repl_platform | B43: Коэф. замещения труда: платформа (подъём/станции передачи) | C43: доля | D43: 0.6 | E43: 0.4 | F43: 0.9 | G43: Допущение команды | H43: допущение
A44: Aer_repl_tow | B44: Коэф. замещения труда: буксировка | C44: доля | D44: 0.8 | E44: 0.5 | F44: 0.9 | G44: Допущение команды: сцепка тележек остаётся ручной | H44: допущение
...

Sheet Медучреждение
A1: ОБЪЕКТ: МЕДУЧРЕЖДЕНИЕ — процесс: внутрибольничная транспортировка тележек (питание, бельё, отходы, расходники)
A2: Синие ячейки — ввод; жёлтая заливка — допущения команды; чёрные — формулы. Результаты помечены зелёной заливкой.
A4: БЛОК 1. ПАРАМЕТРЫ ОБЪЕКТА (демо-датасет организатора, лист «Медучреждение»)
A5: Код | B5: Параметр | C5: Ед. изм. | D5: Значение | E5: Min | F5: Max | G5: Источник / обоснование | H5: Тип
A6: Med_S_total | B6: Общая площадь здания(й) | C6: м² | D6: 45000 | E6: 3000 | F6: 200000 | G6: Датасет, лист «Медучреждение» | H6: датасет
A7: Med_floors | B7: Количество этажей (основной корпус) | C7: шт. | D7: 9 | E7: 3 | F7: 20 | G7: Датасет, лист «Медучреждение» | H7: датасет
A8: Med_lifts | B8: Количество лифтов (грузовых/медицинских) | C8: шт. | D8: 4 | E8: 1 | F8: 12 | G8: Датасет, лист «Медучреждение» | H8: датасет
A9: Med_beds | B9: Количество коек | C9: коек | D9: 650 | E9: 50 | F9: 2500 | G9: Датасет, лист «Медучреждение» | H9: датасет
A10: Med_feedings | B10: Количество кормлений в сутки | C10: раз/сут | D10: 3 | E10: 3 | F10: 5 | G10: Датасет, лист «Медучреждение» | H10: датасет
A11: Med_food_points | B11: Количество точек раздачи питания (отделений) | C11: шт. | D11: 18 | E11: 4 | F11: 60 | G11: Датасет, лист «Медучреждение» | H11: датасет
A12: Med_L_food | B12: Среднее расстояние от пищеблока до отделения | C12: м | D12: 180 | E12: 30 | F12: 500 | G12: Датасет, лист «Медучреждение» | H12: датасет
A13: Med_cart_mass | B13: Средняя масса тележки с питанием (брутто) | C13: кг | D13: 120 | E13: 40 | F13: 250 | G13: Датасет, лист «Медучреждение» | H13: датасет
A14: Med_linen_points | B14: Количество точек сбора/выдачи белья | C14: шт. | D14: 18 | E14: 4 | F14: 60 | G14: Датасет, лист «Медучреждение» | H14: датасет
A15: Med_linen_freq | B15: Периодичность смены белья | C15: раз/сут | D15: 1.3 | E15: 1 | F15: 3 | G15: Датасет, лист «Медучреждение» | H15: датасет
A16: Med_linen_mass | B16: Средняя масса контейнера с бельём | C16: кг | D16: 55 | E16: 20 | F16: 120 | G16: Датасет, лист «Медучреждение» | H16: датасет
A17: Med_supplies_trips | B17: Объём доставки расходных материалов | C17: рейсов/сут | D17: 45 | E17: 10 | F17: 200 | G17: Датасет, лист «Медучреждение» | H17: датасет
... A30: Med_horizon | B30: Горизонт расчёта окупаемости | C30: лет | D30: 7 | E30: 5 | F30: 15 | G30: Датасет, лист «Медучреждение» | H30: датасет
A32: БЛОК 2. ПАРАМЕТРЫ ПРОЦЕССА И ДОПУЩЕНИЯ КОМАНДЫ
A33: Код | B33: Параметр | C33: Ед. изм. | D33: Значение | E33: Min | F33: Max | G33: Источник / обоснование | H33: Тип
A34: Med_shifts | B34: Смен в сутки (стационар 24/7) | C34: смен | D34: 3 | E34: 2 | F34: 3 | G34: Датасет: 3 смены медперсонала | H34: датасет
A35: Med_hours_day | B35: Часов логистической работы в сутки (окно 06:00–22:00) | C35: ч | D35: 16 | E35: 8 | F35: 24 | G35: Допущение команды: ночью доставки минимальны (шум ≤30 дБА в палатах) | H35: допущение
A36: Med_peak_k | B36: Пиковый коэффициент (пики 07–10 и 15–17 по датасету) | C36: коэф. | D36: 1.8 | E36: 1.2 | F36: 2.5 | G36: Допущение команды: два пиковых окна | H36: допущение
A37: Med_ops_food | B37: Рейсы питания = кормлений × отделений × 2 (доставка + возврат тележек) | C37: оп./сут | D37: =Med_feedings*Med_food_points*2 -> 108 | G37: Формула из датасета | H37: формула
A38: Med_ops_linen | B38: Рейсы белья = точек × периодичность × 2 (чистое + грязное) | C38: оп./сут | D38: =Med_linen_points*Med_linen_freq*2 -> 46.8 | G38: Формула из датасета | H38: формула
A39: Med_ops_waste | B39: Рейсы отходов = точек × периодичность × 2 (вывоз + возврат тары) | C39: оп./сут | D39: =Med_waste_points*Med_waste_freq*2 -> 80 | G39: Формула из датасета | H39: формула
A40: Med_ops_supplies | B40: Рейсы расходных материалов | C40: оп./сут | D40: =Med_supplies_trips -> 45 | G40: Датасет | H40: формула
A41: Med_ops_day | B41: Объём операций процесса = питание + бельё + отходы + расходники | C41: оп./сут | D41: =Med_ops_food+Med_ops_linen+Med_ops_waste+Med_ops_supplies -> 279.8 | G41: Формула | H41: формула
A42: Med_peak_ops_h | B42: Пиковая интенсивность = объём / часов × пиковый коэффициент | C42: оп./ч | D42: =Med_ops_day/Med_hours_day*Med_peak_k -> 31.4775 | G42: Формула | H42: формула
A43: Med_auto_share | B43: Доля автоматизируемых операций | C43: доля | D43: 0.9 | E43: 0.5 | F43: 1 | G43: Допущение: 10% маршрутов (реанимация, оперблок, режимные зоны) остаются ручными | H43: допущение
A44: Med_unit_mass | B44: Масса единицы груза = максимальная из тележек процесса | C44: кг | D44: =MAX(Med_cart_mass,Med_linen_mass) -> 120 | G44: Формула из датасета | H44: формула
A45: Med_divisible | B45: Груз делимый (0 — тележка неделима) | C45: 1/0 | D45: 0 | E45: 0 | F45: 1 | G45: Допущение | H45: допущение
A46: Med_L | B46: Средняя длина маршрута (пищеблок ↔ отделение) | C46: м | D46: =Med_L_food -> 180 | G46: Датасет | H46: формула
A47: Med_speed_cap | B47: Ограничение скорости в коридорах | C47: м/с | D47: 1 | E47: 0.5 | F47: 1.5 | G47: Допущение: безопасность пациентов, разминовка с каталками | H47: допущение
A48: Med_lift_share | B48: Доля рейсов с использованием лифта | C48: доля | D48: 0.8 | E48: 0 | F48: 1 | G48: Допущение: 9 этажей, пищеблок/прачечная на нижних этажах | H48: допущение
A49: Med_lift_time | B49: Ожидание + проезд лифта (в один проход) | C49: с | D49: 180 | E49: 60 | F49: 600 | G49: Допущение команды: 4 лифта на 9 этажей — типичное узкое место (датасет) | H49: допущение
A50: Med_aisle | B50: Минимальная ширина прохода | C50: м | D50: =Med_corridor -> 2.4 | G50: Датасет | H50: формула
A51: Med_clearance | B51: Запас по ширине (разминовка с каталкой) | C51: м | D51: 0.9 | E51: 0.5 | F51: 1.5 | G51: Допущение: каталка ~0.7 м + зазоры | H51: допущение
A52: Med_outdoor_req | B52: Требуется уличная эксплуатация | C52: 1/0 | D52: 0 | E52: 0 | F52: 1 | G52: Внутрибольничная логистика | H52: датасет
A53: Med_task_class | B53: Класс задачи процесса | D53: транспорт | G53: транспорт (рейсы) / уборка (площадь) | H53: датасет
A54: Med_handling_req | B54: Допустимые способы обработки груза (через ;) | D54: платформа;кузов | G54: Допущение команды: тележки подхватываются платформой напрямую (→ 0.8); кузов — мелкие грузы | H54: допущение
...

Sheet Сравнение
A1: СВОДНЫЙ ДАШБОРД: три типа объектов × сценарии (значения подтягиваются с листов объектов)
A3: Объект | B3: Сценарий | C3: Решение | D3: Роботов | E3: CAPEX, руб. | F3: OPEX процесса, руб./год | G3: Чистый годовой эффект, руб./год | H3: Окупаемость, лет | I3: ROI за горизонт | J3: NPV, руб. | K3: TCO решения, руб. | L3: Интерпретация | M3: Риски
A4: Склад | B4: База (без роботизации) | C4: — | D4: 0 | E4: 0 | F4: =Склад!D180 -> 46872000
A5: Склад | B5: Покупка A | C5: =Склад!E173 -> Ronavi H1500 (AMR, до 1500 кг) | D5: =Склад!E176 -> 12 | E5: =Склад!E178 -> 46339150 | F5: =Склад!E180 -> 31382572 | G5: =Склад!E184 -> 15489428 | H5: =Склад!E186 -> 2.9916631 | I5: =Склад!E187 -> 1.6013919 | J5: =Склад!E206 -> 10165005 | K5: =Склад!E188 -> 89312010 | L5: =Склад!E190 -> Средняя целесообразность (2–4 лет) — рекомендован пилот | M5: =Склад!E191
A6: Склад | B6: RaaS A | C6: =Склад!F173 -> DMR Carrier P (FMR, вилочный AMR) | D6: =Склад!F176 -> 15 | E6: =Склад!F178 -> 10643050 | F6: =Склад!F180 -> 43675570 | G6: =Склад!F184 -> 3196430 | H6: =Склад!F186 -> 3.3296678 | I6: =Склад!F187 -> 1.5016513 | J6: =Склад!H206 -> 1473934.6 | K6: =Склад!F188 -> 111840900 | L6: =Склад!F190 -> Средняя целесообразность (2–4 лет) — рекомендован пилот | M6: =Склад!F191 -> Зрелость: статус «piloting»; ТТХ требуют подтверждения;
A7: Склад | B7: Покупка B | C7: =Склад!G173 -> Ronavi H1500 (AMR, до 1500 кг) | D7: =Склад!G176 -> 12 | E7: =Склад!G178 -> 46339150 | F7: =Склад!G180 -> 54818572 | G7: =Склад!G184 -> -7946572 | H7: =Склад!G186 -> не окупается | I7: =Склад!G187 -> -0.92735538 | J7: =Склад!K206 -> -78675874 | K7: =Склад!G188 -> 89312010 | L7: =Склад!G190 -> Не окупается: годовой эффект ≤ 0 | M7: =Склад!G191
A9: Аэропорт | B9: База (без роботизации) | C9: — | D9: 0 | E9: 0 | F9: =Аэропорт!D180 -> 99993600
A10: Аэропорт | B10: Покупка A | C10: =Аэропорт!E173 -> Беспилотный тягач (Cognitive Pilot) | D10: =Аэропорт!E176 -> 17 | E10: =Аэропорт!E178 -> 104290450 | F10: =Аэропорт!E180 -> 40836012 | G10: =Аэропорт!E184 -> 60770388 | H10: =Аэропорт!E186 -> 1.7161393 | I10: =Аэропорт!E187 -> 4.0137205 | J10: =Аэропорт!E206 -> 1.8692076e+08 | K10: =Аэропорт!E188 -> 200955078 | L10: =Аэропорт!E190 -> Высокая целесообразность (окупаемость до 2 лет) | M10: =Аэропорт!E191 -> низкая среднесуточная загрузка парка (парк рассчитан на пик) — рассмотреть частичную роботизацию или RaaS;
A11: Аэропорт | B11: RaaS A | C11: =Аэропорт!F173 -> Беспилотный тягач (Cognitive Pilot) | D11: =Аэропорт!F176 -> 17 | E11: =Аэропорт!F178 -> 18260550 | F11: =Аэропорт!F180 -> 50356012 | G11: =Аэропорт!F184 -> 51250388 | H11: =Аэропорт!F186 -> 0.35630072 | I11: =Аэропорт!F187 -> 19.646326 | J11: =Аэропорт!H206 -> 2.312478e+08 | K11: =Аэропорт!F188 -> 174765178 | L11: =Аэропорт!F190 -> Высокая целесообразность (окупаемость до 2 лет) | M11: =Аэропорт!F191 -> низкая среднесуточная загрузка парка (парк рассчитан на пик) — рассмотреть частичную роботизацию или RaaS;
A12: Аэропорт | B12: Покупка B | C12: =Аэропорт!G173 -> EVOCARGO N1 (беспилотный электрогрузовик) | D12: =Аэропорт!G176 -> 39 | E12: =Аэропорт!G178 -> 350812550 | F12: =Аэропорт!G180 -> 57667276 | G12: =Аэропорт!G184 -> 43939124 | H12: =Аэропорт!G186 -> 7.9840588 | I12: =Аэропорт!G187 -> 0.81004476 | J12: =Аэропорт!K206 -> -1.5288101e+08 | K12: =Аэропорт!G188 -> 581896026 | L12: =Аэропорт!G190 -> Низкая целесообразность (более 4 лет) — требует уточнения данных | M12: =Аэропорт!G191 -> CAPEX выше планового бюджета; низкая среднесуточная загрузка парка (парк рассчитан на пик) — рассмотреть частичную роботизацию или RaaS;
A14: Медучреждение | B14: База (без роботизации) | C14: — | D14: 0 | E14: 0 | F14: =Медучреждение!D196 -> 42486343
A15: Медучреждение | B15: Покупка A | C15: =Медучреждение!E189 -> Ronavi M (AMR для стеллажей/тележек, до 1200 кг) | D15: =Медучреждение!E192 -> 9 | E15: =Медучреждение!E194 -> 36020050 | F15: =Медучреждение!E196 -> 18077638 | G15: =Медучреждение!E200 -> 25297923 | H15: =Медучреждение!E202 -> 1.4238343 | I15: =Медучреждение!E203 -> 4.8563359 | J15: =Медучреждение!E222 -> 85665526 | K15: =Медучреждение!E204 -> 81450284 | L15: =Медучреждение!E206 -> Высокая целесообразность (окупаемость до 2 лет) | M15: =Медучреждение!E207 -> Зрелость: статус «piloting»; ТТХ требуют подтверждения; CAPEX выше планового бюджета;
A16: Медучреждение | B16: RaaS A | C16: =Медучреждение!F189 -> Ronavi M (AMR для стеллажей/тележек, до 1200 кг) | D16: =Медучреждение!F192 -> 9 | E16: =Медучреждение!F194 -> 8690550 | F16: =Медучреждение!F196 -> 21101638 | G16: =Медучреждение!F200 -> 22273923 | H16: =Медучреждение!F202 -> 0.39016701 | I16: =Медучреждение!F203 -> 17.941035 | J16: =Медучреждение!H222 -> 99748236 | K16: =Медучреждение!F204 -> 73128784 | L16: =Медучреждение!F206 -> Высокая целесообразность (окупаемость до 2 лет) | M16: =Медучреждение!F207 -> Зрелость: статус «piloting»; ТТХ требуют подтверждения;
A17: Медучреждение | B17: Покупка B | C17: =Медучреждение!G189 -> AMR 800 (Морос, до 800 кг) | D17: =Медучреждение!G192 -> 9 | E17: =Медучреждение!G194 -> 27704050 | F17: =Медучреждение!G196 -> 17537638 | G17: =Медучреждение!G200 -> 25837923 | H17: =Медучреждение!G202 -> 1.0722243 | I17: =Медучреждение!G203 -> 6.4700093 | J17: =Медучреждение!K222 -> 96979299 | K17: =Медучреждение!G204 -> 68814284 | L17: =Медучреждение!G206 -> Высокая целесообразность (окупаемость до 2 лет) | M17: =Медучреждение!G207 -> ТТХ требуют подтверждения;
A20: Все результаты — предварительная оценка (экспресс-предынвестиционная); требуют верификации при обследовании объекта (ТЗ п.3.7.5). Все формулы, единицы измерения, источники и допущения доступны на листах объектов и «Нормативы» (ТЗ п.3.5.8).
